Workbook
Name SegmentaciónDeDatos_Tipo_Comercio: #N/A
Name SegmentaciónDeDatos_Tipo_Comercio1: #N/A

Sheet 00_Indice
B3: Hoja | C3: Contenido
B4: 01_Base | C4: Base consolidada
B5: 02_Cálculos_Anexos | C5: Tablas analíticas en formato granular
B6: 03_KPIs | C6: KPIs mensuales
B7: 04_Gráficos | C7: Visuales principales
B8: 05_DQC | C8: Validaciones de calidad
B9: 06_RFT | C9: Segmentación R/F/T
B10: 07_I&R | C10: Resumen ejecutivo

Sheet 01_Base
A1: <<INDICE
A3: Mes | B3: ID_Cliente | C3: Segmento_Actual | D3: Tipo_Comercio | E3: ID_Transaccion | F3: Fecha_Compra | G3: Monto_RD
A4: 44927 | B4: 3287 | C4: Joven | D4: SUPERMERCADOS | E4: 1 | F4: 44937 | G4: 680.14
A5: 44927 | B5: 4453 | C5: Joven | D5: GASOLINERAS | E5: 2 | F5: 44940 | G5: 1051.59
A6: 44927 | B6: 1205 | C6: Premium | D6: SUPERMERCADOS | E6: 3 | F6: 44937 | G6: 1111.4
A7: 44927 | B7: 552 | C7: Joven | D7: SUPERMERCADOS | E7: 4 | F7: 44949 | G7: 2406.93
A8: 44927 | B8: 6437 | C8: Premium | D8: MODA | E8: 5 | F8: 44939 | G8: 1994.11
A9: 44927 | B9: 6418 | C9: Joven | D9: FARMACIAS | E9: 6 | F9: 44931 | G9: 1213.61
A10: 44927 | B10: 1939 | C10: Premium | D10: FARMACIAS | E10: 7 | F10: 44940 | G10: 116.51
A11: 44927 | B11: 4078 | C11: Masivo | D11: GASOLINERAS | E11: 8 | F11: 44935 | G11: 976.12
A12: 44927 | B12: 118 | C12: Masivo | D12: ELECTRONICA | E12: 9 | F12: 44950 | G12: 6537.43
A13: 44927 | B13: 822 | C13: Joven | D13: RESTAURANTES | E13: 10 | F13: 44938 | G13: 1052.61
A14: 44927 | B14: 2979 | C14: Masivo | D14: ELECTRONICA | E14: 11 | F14: 44952 | G14: 6296.32
A15: 44927 | B15: 5991 | C15: Joven | D15: GASOLINERAS | E15: 12 | F15: 44947 | G15: 2609.2
... A21370: 44986 | B21370: 240 | C21370: Masivo | D21370: ELECTRONICA | E21370: 21620 | F21370: 44989 | G21370: 4816.18

Sheet 02_Cálculos_Anexos
A1: <<INDICE | B1: KPIs>> | AB1: RFT
A3: Clientes activos | G3: Transacciones totales | L3: Frecuencia promedio | Q3: Ticket promedio | V3: Participación por tipo de comercio y segmento (cantidad de transacciones) | AC3: R/F/T por cliente (y por segmento) | AK3: Participación por tipo de comercio (cantidad de transacciones)
A4: Mes | B4: Segmento_Actual | C4: Tipo_Comercio | D4: Clientes_Activos | G4: Mes | H4: Segmento_Actual | I4: Tipo_Comercio | J4: Transacciones_Totales | L4: Mes | M4: Segmento_Actual | N4: Tipo_Comercio | O4: Frecuencia_Promedio | Q4: Mes | R4: Segmento_Actual | S4: Tipo_Comercio | T4: Ticket_Promedio | V4: Mes | W4: Segmento_Actual | X4: Tipo_Comercio | Y4: Participacion_Tipo | AC4: ID_CLIENTE | AD4: SEGMENTO_ACTUAL | AE4: Recencia | AF4: Frecuencia | AG4: Ticket_Promedio | AK4: Mes | AL4: Tipo_Comercio | AM4: Participacion_comercio
A5: 01-2023 | B5: Empresarial | C5: Ecommerce | D5: 34 | G5: 44927 | H5: Joven | I5: Ecommerce | J5: 90 | L5: 44927 | M5: Empresarial | N5: Ecommerce | O5: 1.0588235 | Q5: 44927 | R5: Joven | S5: Ecommerce | T5: 2872.5426 | V5: 44927 | W5: Empresarial | X5: Ecommerce | Y5: 0.10557185 | AC5: 1 | AD5: Empresarial | AE5: 41 | AF5: 2 | AG5: 1330.54 | AK5: 44927 | AL5: ECOMMERCE | AM5: 0.10122219
A6: 01-2023 | B6: Empresarial | C6: Electronica | D6: 29 | G6: 45017 | H6: Joven | I6: Restaurantes | J6: 182 | L6: 44927 | M6: Empresarial | N6: Electronica | O6: 1.0344828 | Q6: 45017 | R6: Joven | S6: Restaurantes | T6: 1212.6774 | V6: 44927 | W6: Empresarial | X6: Moda | Y6: 0.12316716 | AC6: 2 | AD6: Joven | AE6: 80 | AF6: 3 | AG6: 2000.51 | AK6: 44927 | AL6: MODA | AM6: 0.1212786
A7: 01-2023 | B7: Empresarial | C7: Farmacias | D7: 51 | G7: 44986 | H7: Empresarial | I7: Supermercados | J7: 92 | L7: 44927 | M7: Empresarial | N7: Farmacias | O7: 1.0196078 | Q7: 44986 | R7: Empresarial | S7: Supermercados | T7: 1620.4157 | V7: 44927 | W7: Empresarial | X7: Electronica | Y7: 0.08797654 | AC7: 3 | AD7: Masivo | AE7: 13 | AF7: 6 | AG7: 1312.35 | AK7: 44927 | AL7: GASOLINERAS | AM7: 0.10874334
A8: 01-2023 | B8: Empresarial | C8: Gasolineras | D8: 40 | G8: 45078 | H8: Premium | I8: Farmacias | J8: 139 | L8: 44927 | M8: Empresarial | N8: Gasolineras | O8: 1.05 | Q8: 45078 | R8: Premium | S8: Farmacias | T8: 800.24396 | V8: 44927 | W8: Empresarial | X8: Supermercados | Y8: 0.25513196 | AC8: 4 | AD8: Masivo | AE8: 39 | AF8: 6 | AG8: 2241.62 | AK8: 44927 | AL8: FARMACIAS | AM8: 0.15543717
A9: 01-2023 | B9: Empresarial | C9: Moda | D9: 40 | G9: 44958 | H9: Empresarial | I9: Restaurantes | J9: 43 | L9: 44927 | M9: Empresarial | N9: Moda | O9: 1.05 | Q9: 44958 | R9: Empresarial | S9: Restaurantes | T9: 1179.1426 | V9: 44927 | W9: Empresarial | X9: Restaurantes | Y9: 0.15249267 | AC9: 5 | AD9: Masivo | AE9: 66 | AF9: 6 | AG9: 1528.12 | AK9: 44927 | AL9: ELECTRONICA | AM9: 0.075838295
A10: 01-2023 | B10: Empresarial | C10: Restaurantes | D10: 50 | G10: 45078 | H10: Empresarial | I10: Moda | J10: 35 | L10: 44927 | M10: Empresarial | N10: Restaurantes | O10: 1.04 | Q10: 45078 | R10: Empresarial | S10: Moda | T10: 3477.226 | V10: 44927 | W10: Empresarial | X10: Gasolineras | Y10: 0.12316716 | AC10: 7 | AD10: Masivo | AE10: 6 | AF10: 2 | AG10: 2462.63 | AK10: 44927 | AL10: SUPERMERCADOS | AM10: 0.26888123
A11: 01-2023 | B11: Empresarial | C11: Supermercados | D11: 77 | G11: 45047 | H11: Masivo | I11: Electronica | J11: 196 | L11: 44927 | M11: Empresarial | N11: Supermercados | O11: 1.1298701 | Q11: 45047 | R11: Masivo | S11: Electronica | T11: 5148.0371 | V11: 44927 | W11: Empresarial | X11: Farmacias | Y11: 0.15249267 | AC11: 8 | AD11: Masivo | AE11: 49 | AF11: 3 | AG11: 2232.04 | AK11: 44927 | AL11: RESTAURANTES | AM11: 0.16859919
A12: 01-2023 | B12: Joven | C12: Ecommerce | D12: 89 | G12: 44986 | H12: Masivo | I12: Farmacias | J12: 277 | L12: 44927 | M12: Joven | N12: Ecommerce | O12: 1.011236 | Q12: 44986 | R12: Masivo | S12: Farmacias | T12: 779.53025 | V12: 44927 | W12: Joven | X12: Farmacias | Y12: 0.14796547 | AC12: 9 | AD12: Masivo | AE12: 12 | AF12: 6 | AG12: 3114.59 | AK12: 44958 | AL12: GASOLINERAS | AM12: 0.1147541
A13: 01-2023 | B13: Joven | C13: Electronica | D13: 54 | G13: 45047 | H13: Premium | I13: Ecommerce | J13: 69 | L13: 44927 | M13: Joven | N13: Electronica | O13: 1.0185185 | Q13: 45047 | R13: Premium | S13: Ecommerce | T13: 2988.6338 | V13: 44927 | W13: Joven | X13: Restaurantes | Y13: 0.16892725 | AC13: 10 | AD13: Joven | AE13: 67 | AF13: 3 | AG13: 1553.12 | AK13: 44958 | AL13: SUPERMERCADOS | AM13: 0.26168792
A14: 01-2023 | B14: Joven | C14: Farmacias | D14: 112 | G14: 45017 | H14: Joven | I14: Electronica | J14: 124 | L14: 44927 | M14: Joven | N14: Farmacias | O14: 1.0714286 | Q14: 45017 | R14: Joven | S14: Electronica | T14: 5503.117 | V14: 44927 | W14: Joven | X14: Electronica | Y14: 0.067817509 | AC14: 11 | AD14: Premium | AE14: 77 | AF14: 2 | AG14: 3426.06 | AK14: 44958 | AL14: ELECTRONICA | AM14: 0.084092289
A15: 01-2023 | B15: Joven | C15: Gasolineras | D15: 80 | G15: 45017 | H15: Premium | I15: Gasolineras | J15: 97 | L15: 44927 | M15: Joven | N15: Gasolineras | O15: 1.05 | Q15: 45017 | R15: Premium | S15: Gasolineras | T15: 2187.5454 | V15: 44927 | W15: Joven | X15: Supermercados | Y15: 0.29346486 | AC15: 12 | AD15: Joven | AE15: 79 | AF15: 5 | AG15: 2876.68 | AK15: 44958 | AL15: RESTAURANTES | AM15: 0.17547055
A16: 01-2023 | B16: Joven | C16: Moda | D16: 85 | G16: 44986 | H16: Joven | I16: Farmacias | J16: 122 | L16: 44927 | M16: Joven | N16: Moda | O16: 1.0235294 | Q16: 44986 | R16: Joven | S16: Farmacias | T16: 756.6827 | V16: 44927 | W16: Joven | X16: Moda | Y16: 0.10727497 | AC16: 13 | AD16: Empresarial | AE16: 42 | AF16: 2 | AG16: 2180.15 | AK16: 44958 | AL16: FARMACIAS | AM16: 0.14632665
... A46: 02-2023 | B46: Joven | C46: Supermercados | D46: 200 | G46: 45017 | H46: Masivo | I46: Electronica | J46: 174 | L46: 44958 | M46: Joven | N46: Supermercados | O46: 1.08 | Q46: 45017 | R46: Masivo | S46: Electronica | T46: 5251.8758 | V46: 44958 | W46: Joven | X46: Ecommerce | Y46: 0.10823529 | AC46: 54 | AD46: Joven | AE46: 16 | AF46: 3 | AG46: 2070.94 | AK46: 45078 | AL46: ECOMMERCE | AM46: 0.093657086
A47: 02-2023 | B47: Masivo | C47: Ecommerce | D47: 140 | G47: 45078 | H47: Premium | I47: Gasolineras | J47: 83 | L47: 44958 | M47: Masivo | N47: Ecommerce | O47: 1.0357143 | Q47: 45078 | R47: Premium | S47: Gasolineras | T47: 1956.9484 | V47: 44958 | W47: Masivo | X47: Ecommerce | Y47: 0.096925134 | AC47: 55 | AD47: Masivo | AE47: 5 | AF47: 6 | AG47: 3155.15
A48: 02-2023 | B48: Masivo | C48: Electronica | D48: 107 | G48: 44986 | H48: Premium | I48: Farmacias | J48: 100 | L48: 44958 | M48: Masivo | N48: Electronica | O48: 1.0373832 | Q48: 44986 | R48: Premium | S48: Farmacias | T48: 740.968 | V48: 44958 | W48: Masivo | X48: Farmacias | Y48: 0.15173797 | AC48: 56 | AD48: Masivo | AE48: 48 | AF48: 4 | AG48: 859.15
A49: 02-2023 | B49: Masivo | C49: Farmacias | D49: 215 | G49: 45017 | H49: Premium | I49: Electronica | J49: 79 | L49: 44958 | M49: Masivo | N49: Farmacias | O49: 1.055814 | Q49: 45017 | R49: Premium | S49: Electronica | T49: 4892.1694 | V49: 44958 | W49: Masivo | X49: Gasolineras | Y49: 0.11764706 | AC49: 58 | AD49: Joven | AE49: 60 | AF49: 2 | AG49: 1150.94
A50: 02-2023 | B50: Masivo | C50: Gasolineras | D50: 170 | G50: 44986 | H50: Empresarial | I50: Restaurantes | J50: 64 | L50: 44958 | M50: Masivo | N50: Gasolineras | O50: 1.0352941 | Q50: 44986 | R50: Empresarial | S50: Restaurantes | T50: 1159.7161 | V50: 44958 | W50: Masivo | X50: Restaurantes | Y50: 0.16911765 | AC50: 60 | AD50: Masivo | AE50: 6 | AF50: 4 | AG50: 2105.17
A51: 02-2023 | B51: Masivo | C51: Moda | D51: 160 | G51: 45078 | H51: Empresarial | I51: Gasolineras | J51: 38 | L51: 44958 | M51: Masivo | N51: Moda | O51: 1.0375 | Q51: 45078 | R51: Empresarial | S51: Gasolineras | T51: 2076.5968 | V51: 44958 | W51: Masivo | X51: Electronica | Y51: 0.074197861 | AC51: 61 | AD51: Masivo | AE51: 67 | AF51: 4 | AG51: 3594.41
A52: 02-2023 | B52: Masivo | C52: Restaurantes | D52: 239 | G52: 44986 | H52: Masivo | I52: Restaurantes | J52: 274 | L52: 44958 | M52: Masivo | N52: Restaurantes | O52: 1.0585774 | Q52: 44986 | R52: Masivo | S52: Restaurantes | T52: 1191.4729 | V52: 44958 | W52: Masivo | X52: Moda | Y52: 0.11096257 | AC52: 62 | AD52: Masivo | AE52: 3 | AF52: 5 | AG52: 2118.82
A53: 02-2023 | B53: Masivo | C53: Supermercados | D53: 394 | G53: 45017 | H53: Premium | I53: Restaurantes | J53: 140 | L53: 44958 | M53: Masivo | N53: Supermercados | O53: 1.0609137 | Q53: 45017 | R53: Premium | S53: Restaurantes | T53: 1172.7685 | V53: 44958 | W53: Masivo | X53: Supermercados | Y53: 0.27941176 | AC53: 63 | AD53: Masivo | AE53: 4 | AF53: 4 | AG53: 890.26
A54: 02-2023 | B54: Premium | C54: Ecommerce | D54: 75 | G54: 44958 | H54: Premium | I54: Restaurantes | J54: 118 | L54: 44958 | M54: Premium | N54: Ecommerce | O54: 1.0533333 | Q54: 44958 | R54: Premium | S54: Restaurantes | T54: 1262.978 | V54: 44958 | W54: Premium | X54: Electronica | Y54: 0.079877112 | AC54: 64 | AD54: Joven | AE54: 39 | AF54: 4 | AG54: 2508.77
A55: 02-2023 | B55: Premium | C55: Electronica | D55: 50 | G55: 45078 | H55: Premium | I55: Restaurantes | J55: 159 | L55: 44958 | M55: Premium | N55: Electronica | O55: 1.04 | Q55: 45078 | R55: Premium | S55: Restaurantes | T55: 1214.123 | V55: 44958 | W55: Premium | X55: Farmacias | Y55: 0.13978495 | AC55: 65 | AD55: Premium | AE55: 45 | AF55: 3 | AG55: 1304.04
A56: 02-2023 | B56: Premium | C56: Farmacias | D56: 85 | G56: 44958 | H56: Masivo | I56: Ecommerce | J56: 145 | L56: 44958 | M56: Premium | N56: Farmacias | O56: 1.0705882 | Q56: 44958 | R56: Masivo | S56: Ecommerce | T56: 2992.3874 | V56: 44958 | W56: Premium | X56: Ecommerce | Y56: 0.12135177 | AC56: 67 | AD56: Masivo | AE56: 173 | AF56: 1 | AG56: 2503.17
A57: 02-2023 | B57: Premium | C57: Gasolineras | D57: 84 | G57: 44927 | H57: Joven | I57: Gasolineras | J57: 84 | L57: 44958 | M57: Premium | N57: Gasolineras | O57: 1 | Q57: 44927 | R57: Joven | S57: Gasolineras | T57: 1995.3074 | V57: 44958 | W57: Premium | X57: Moda | Y57: 0.10599078 | AC57: 68 | AD57: Masivo | AE57: 24 | AF57: 5 | AG57: 1975.84
A58: 02-2023 | B58: Premium | C58: Moda | D58: 68 | G58: 44927 | H58: Empresarial | I58: Ecommerce | J58: 36 | L58: 44958 | M58: Premium | N58: Moda | O58: 1.0147059 | Q58: 44927 | R58: Empresarial | S58: Ecommerce | T58: 3129.4156 | V58: 44958 | W58: Premium | X58: Restaurantes | Y58: 0.1812596 | AC58: 69 | AD58: Masivo | AE58: 19 | AF58: 4 | AG58: 1390.74
... A172: 06-2023 | B172: Premium | C172: Supermercados | D172: 144 | G172: 45078 | H172: Joven | I172: Moda | J172: 100 | L172: 45078 | M172: Premium | N172: Supermercados | O172: 1.1319444 | Q172: 45078 | R172: Joven | S172: Moda | T172: 2532.6059 | V172: 45078 | W172: Premium | X172: Gasolineras | Y172: 0.10627401 | AC172: 195 | AD172: Premium | AE172: 38 | AF172: 2 | AG172: 1365.91
AC173: 196 | AD173: Masivo | AE173: 18 | AF173: 6 | AG173: 2438.49
AC174: 197 | AD174: Masivo | AE174: 22 | AF174: 6 | AG174: 1254.7
AC175: 198 | AD175: Empresarial | AE175: 66 | AF175: 5 | AG175: 1683
AC176: 199 | AD176: Masivo | AE176: 43 | AF176: 3 | AG176: 2317.99
AC177: 200 | AD177: Premium | AE177: 5 | AF177: 5 | AG177: 908.1
AC178: 201 | AD178: Joven | AE178: 11 | AF178: 7 | AG178: 2587.66
AC179: 202 | AD179: Joven | AE179: 47 | AF179: 1 | AG179: 767.08
AC180: 203 | AD180: Joven | AE180: 57 | AF180: 4 | AG180: 2518.3
AC181: 204 | AD181: Empresarial | AE181: 45 | AF181: 5 | AG181: 2414.8
AC182: 205 | AD182: Premium | AE182: 88 | AF182: 1 | AG182: 3742.62
AC183: 206 | AD183: Joven | AE183: 108 | AF183: 3 | AG183: 1237.5
...

Sheet 03_KPIs
B1: <<INDICE | C1: <<Anexos
B3: KPIS
B5: Clientes Activos | K5: Transacciones Totales | U5: Frecuencia Promedio (Transacciones promedio por cliente activo) | AD5: Ticket promedio | AN5: Participacion por Tipo de comercio | AW5: Suma de Participacion_comercio | AX5: Etiquetas de columna
B6: Segmento/Tipo Comercio | C6: 01-2023 | D6: 02-2023 | E6: 03-2023 | F6: 04-2023 | G6: 05-2023 | H6: 06-2023 | I6: Total general | K6: Segmento/Tipo Comercio | L6: 44927 | M6: 44958 | N6: 44986 | O6: 45017 | P6: 45047 | Q6: 45078 | R6: Total general | U6: Segmento/Tipo Comercio | V6: 44927 | W6: 44958 | X6: 44986 | Y6: 45017 | Z6: 45047 | AA6: 45078 | AB6: Promedio general | AD6: Segmento/Tipo Comercio | AE6: 44927 | AF6: 44958 | AG6: 44986 | AH6: 45017 | AI6: 45047 | AJ6: 45078 | AK6: Promedio general | AN6: Segmento/Tipo Comercio | AO6: 44927 | AP6: 44958 | AQ6: 44986 | AR6: 45017 | AS6: 45047 | AT6: 45078 | AU6: Total general | AW6: Etiquetas de fila | AX6: GASOLINERAS | AY6: Total general
B7: Empresarial | C7: 321 | D7: 283 | E7: 315 | F7: 338 | G7: 360 | H7: 378 | I7: 1995 | K7: Empresarial | L7: 341 | M7: 297 | N7: 329 | O7: 351 | P7: 395 | Q7: 411 | R7: 2124 | U7: Empresarial | V7: 1.0546835 | W7: 1.0435558 | X7: 1.0367656 | Y7: 1.0346508 | Z7: 1.0865775 | AA7: 1.0772929 | AB7: 1.0555877 | AD7: Empresarial | AE7: 2372.5894 | AF7: 2421.2683 | AG7: 2486.3048 | AH7: 2364.0123 | AI7: 2320.5013 | AJ7: 2465.0444 | AK7: 2404.9534 | AN7: Empresarial | AO7: 1 | AP7: 1 | AQ7: 1 | AR7: 1 | AS7: 1 | AT7: 1 | AU7: 6 | AW7: 44927 | AX7: 0.10874334 | AY7: 0.10874334
B8: Ecommerce | C8: 34 | D8: 35 | E8: 29 | F8: 24 | G8: 36 | H8: 33 | I8: 191 | K8: Ecommerce | L8: 36 | M8: 35 | N8: 29 | O8: 24 | P8: 36 | Q8: 33 | R8: 193 | U8: Ecommerce | V8: 1.0588235 | W8: 1 | X8: 1 | Y8: 1 | Z8: 1 | AA8: 1 | AB8: 1.0098039 | AD8: Ecommerce | AE8: 3129.4156 | AF8: 3790.7837 | AG8: 3573.479 | AH8: 3023.6 | AI8: 2853.0506 | AJ8: 3154.9582 | AK8: 3254.2145 | AN8: Supermercados | AO8: 0.25513196 | AP8: 0.23569024 | AQ8: 0.27963526 | AR8: 0.22222222 | AS8: 0.22278481 | AT8: 0.2189781 | AU8: 1.4344426 | AW8: 44958 | AX8: 0.1147541 | AY8: 0.1147541
B9: Electronica | C9: 29 | D9: 29 | E9: 26 | F9: 36 | G9: 45 | H9: 56 | I9: 221 | K9: Electronica | L9: 30 | M9: 31 | N9: 26 | O9: 36 | P9: 48 | Q9: 67 | R9: 238 | U9: Electronica | V9: 1.0344828 | W9: 1.0689655 | X9: 1 | Y9: 1 | Z9: 1.0666667 | AA9: 1.1964286 | AB9: 1.0610906 | AD9: Electronica | AE9: 5518.041 | AF9: 4921.1584 | AG9: 5456.0485 | AH9: 5348.0525 | AI9: 5591.694 | AJ9: 4932.3709 | AK9: 5294.5609 | AN9: Restaurantes | AO9: 0.15249267 | AP9: 0.14478114 | AQ9: 0.19452888 | AR9: 0.21367521 | AS9: 0.23037975 | AT9: 0.21167883 | AU9: 1.1475365 | AW9: 44986 | AX9: 0.11296948 | AY9: 0.11296948
B10: Farmacias | C10: 51 | D10: 46 | E10: 42 | F10: 46 | G10: 54 | H10: 57 | I10: 296 | K10: Farmacias | L10: 52 | M10: 46 | N10: 46 | O10: 49 | P10: 57 | Q10: 61 | R10: 311 | U10: Farmacias | V10: 1.0196078 | W10: 1 | X10: 1.0952381 | Y10: 1.0652174 | Z10: 1.0555556 | AA10: 1.0701754 | AB10: 1.0509657 | AD10: Farmacias | AE10: 847.30769 | AF10: 764.98522 | AG10: 847.71696 | AH10: 835.25347 | AI10: 750.62035 | AJ10: 789.49311 | AK10: 805.89613 | AN10: Farmacias | AO10: 0.15249267 | AP10: 0.15488215 | AQ10: 0.13981763 | AR10: 0.13960114 | AS10: 0.1443038 | AT10: 0.14841849 | AU10: 0.87951588 | AW10: 45017 | AX10: 0.11889655 | AY10: 0.11889655
B11: Gasolineras | C11: 40 | D11: 33 | E11: 40 | F11: 43 | G11: 35 | H11: 37 | I11: 228 | K11: Gasolineras | L11: 42 | M11: 35 | N11: 42 | O11: 44 | P11: 40 | Q11: 38 | R11: 241 | U11: Gasolineras | V11: 1.05 | W11: 1.0606061 | X11: 1.05 | Y11: 1.0232558 | Z11: 1.1428571 | AA11: 1.027027 | AB11: 1.0589577 | AD11: Gasolineras | AE11: 2002.8186 | AF11: 2280.5449 | AG11: 2042.9567 | AH11: 2132.2941 | AI11: 2094.5525 | AJ11: 2076.5968 | AK11: 2104.9606 | AN11: Gasolineras | AO11: 0.12316716 | AP11: 0.11784512 | AQ11: 0.12765957 | AR11: 0.12535613 | AS11: 0.10126582 | AT11: 0.092457421 | AU11: 0.68775122 | AW11: 45047 | AX11: 0.10097036 | AY11: 0.10097036
B12: Moda | C12: 40 | D12: 36 | E12: 30 | F12: 42 | G12: 33 | H12: 33 | I12: 214 | K12: Moda | L12: 42 | M12: 37 | N12: 30 | O12: 45 | P12: 35 | Q12: 35 | R12: 224 | U12: Moda | V12: 1.05 | W12: 1.0277778 | X12: 1 | Y12: 1.0714286 | Z12: 1.0606061 | AA12: 1.0606061 | AB12: 1.0450697 | AD12: Moda | AE12: 2584.4345 | AF12: 2530.1651 | AG12: 2703.8007 | AH12: 2648.6602 | AI12: 2172.3089 | AJ12: 3477.226 | AK12: 2686.0992 | AN12: Electronica | AO12: 0.08797654 | AP12: 0.1043771 | AQ12: 0.079027356 | AR12: 0.1025641 | AS12: 0.12151899 | AT12: 0.16301703 | AU12: 0.65848112 | AW12: 45078 | AX12: 0.10059465 | AY12: 0.10059465
B13: Restaurantes | C13: 50 | D13: 43 | E13: 60 | F13: 71 | G13: 80 | H13: 78 | I13: 382 | K13: Restaurantes | L13: 52 | M13: 43 | N13: 64 | O13: 75 | P13: 91 | Q13: 87 | R13: 412 | U13: Restaurantes | V13: 1.04 | W13: 1 | X13: 1.0666667 | Y13: 1.056338 | Z13: 1.1375 | AA13: 1.1153846 | AB13: 1.0693149 | AD13: Restaurantes | AE13: 1149.2994 | AF13: 1179.1426 | AG13: 1159.7161 | AH13: 1050.4099 | AI13: 1211.1605 | AJ13: 1147.15 | AK13: 1149.4797 | AN13: Moda | AO13: 0.12316716 | AP13: 0.12457912 | AQ13: 0.09118541 | AR13: 0.12820513 | AS13: 0.088607595 | AT13: 0.085158151 | AU13: 0.64090256 | AW13: Total general | AX13: 0.65692849 | AY13: 0.65692849
B14: Supermercados | C14: 77 | D14: 61 | E14: 88 | F14: 76 | G14: 77 | H14: 84 | I14: 463 | K14: Supermercados | L14: 87 | M14: 70 | N14: 92 | O14: 78 | P14: 88 | Q14: 90 | R14: 505 | U14: Supermercados | V14: 1.1298701 | W14: 1.147541 | X14: 1.0454545 | Y14: 1.0263158 | Z14: 1.1428571 | AA14: 1.0714286 | AB14: 1.0939112 | AD14: Supermercados | AE14: 1376.8087 | AF14: 1482.0983 | AG14: 1620.4157 | AH14: 1509.816 | AI14: 1570.1225 | AJ14: 1677.5158 | AK14: 1539.4628 | AN14: Ecommerce | AO14: 0.10557185 | AP14: 0.11784512 | AQ14: 0.088145897 | AR14: 0.068376068 | AS14: 0.091139241 | AT14: 0.080291971 | AU14: 0.55137014
B15: Joven | C15: 774 | D15: 812 | E15: 836 | F15: 882 | G15: 904 | H15: 951 | I15: 5159 | K15: Joven | L15: 811 | M15: 850 | N15: 870 | O15: 937 | P15: 984 | Q15: 1034 | R15: 5486 | U15: Joven | V15: 1.0402444 | W15: 1.0430021 | X15: 1.0362004 | Y15: 1.066799 | Z15: 1.0757235 | AA15: 1.073479 | AB15: 1.0559081 | AD15: Joven | AE15: 2181.484 | AF15: 2378.9364 | AG15: 2459.6658 | AH15: 2411.889 | AI15: 2286.4003 | AJ15: 2346.7486 | AK15: 2344.1874 | AN15: Joven | AO15: 1 | AP15: 1 | AQ15: 1 | AR15: 1 | AS15: 1 | AT15: 1 | AU15: 6
B16: Ecommerce | C16: 89 | D16: 83 | E16: 86 | F16: 91 | G16: 84 | H16: 109 | I16: 542 | K16: Ecommerce | L16: 90 | M16: 92 | N16: 88 | O16: 104 | P16: 85 | Q16: 111 | R16: 570 | U16: Ecommerce | V16: 1.011236 | W16: 1.1084337 | X16: 1.0232558 | Y16: 1.1428571 | Z16: 1.0119048 | AA16: 1.0183486 | AB16: 1.0526727 | AD16: Ecommerce | AE16: 2872.5426 | AF16: 2687.9345 | AG16: 2960.7698 | AH16: 3096.9228 | AI16: 2879.4508 | AJ16: 2980.8166 | AK16: 2913.0728 | AN16: Supermercados | AO16: 0.29346486 | AP16: 0.25411765 | AQ16: 0.26206897 | AR16: 0.21344717 | AS16: 0.24390244 | AT16: 0.22630561 | AU16: 1.4933067
B17: Electronica | C17: 54 | D17: 82 | E17: 97 | F17: 110 | G17: 113 | H17: 116 | I17: 572 | K17: Electronica | L17: 55 | M17: 83 | N17: 103 | O17: 124 | P17: 122 | Q17: 123 | R17: 610 | U17: Electronica | V17: 1.0185185 | W17: 1.0121951 | X17: 1.0618557 | Y17: 1.1272727 | Z17: 1.079646 | AA17: 1.0603448 | AB17: 1.0599721 | AD17: Electronica | AE17: 4618.07 | AF17: 5387.0351 | AG17: 6008.3797 | AH17: 5503.117 | AI17: 5117.4761 | AJ17: 5246.0711 | AK17: 5313.3582 | AN17: Restaurantes | AO17: 0.16892725 | AP17: 0.19294118 | AQ17: 0.18505747 | AR17: 0.19423693 | AS17: 0.19308943 | AT17: 0.21373308 | AU17: 1.1479853
B18: Farmacias | C18: 112 | D18: 113 | E18: 118 | F18: 126 | G18: 142 | H18: 138 | I18: 749 | K18: Farmacias | L18: 120 | M18: 118 | N18: 122 | O18: 130 | P18: 149 | Q18: 149 | R18: 788 | U18: Farmacias | V18: 1.0714286 | W18: 1.0442478 | X18: 1.0338983 | Y18: 1.031746 | Z18: 1.0492958 | AA18: 1.0797101 | AB18: 1.0517211 | AD18: Farmacias | AE18: 778.91617 | AF18: 951.00847 | AG18: 756.6827 | AH18: 782.91292 | AI18: 751.5 | AJ18: 769.26181 | AK18: 798.38035 | AN18: Farmacias | AO18: 0.14796547 | AP18: 0.13882353 | AQ18: 0.14022989 | AR18: 0.13874066 | AS18: 0.15142276 | AT18: 0.14410058 | AU18: 0.8612829
B19: Gasolineras | C19: 80 | D19: 81 | E19: 93 | F19: 98 | G19: 88 | H19: 93 | I19: 533 | K19: Gasolineras | L19: 84 | M19: 83 | N19: 96 | O19: 102 | P19: 94 | Q19: 96 | R19: 555 | U19: Gasolineras | V19: 1.05 | W19: 1.0246914 | X19: 1.0322581 | Y19: 1.0408163 | Z19: 1.0681818 | AA19: 1.0322581 | AB19: 1.0413676 | AD19: Gasolineras | AE19: 1995.3074 | AF19: 1946.8635 | AG19: 2117.4582 | AH19: 1930.6741 | AI19: 1951.8212 | AJ19: 2061.9755 | AK19: 2000.6833 | AN19: Electronica | AO19: 0.067817509 | AP19: 0.097647059 | AQ19: 0.1183908 | AR19: 0.13233725 | AS19: 0.12398374 | AT19: 0.11895551 | AU19: 0.65913187
B20: Moda | C20: 85 | D20: 94 | E20: 71 | F20: 92 | G20: 99 | H20: 97 | I20: 538 | K20: Moda | L20: 87 | M20: 94 | N20: 72 | O20: 95 | P20: 104 | Q20: 100 | R20: 552 | U20: Moda | V20: 1.0235294 | W20: 1 | X20: 1.0140845 | Y20: 1.0326087 | Z20: 1.0505051 | AA20: 1.0309278 | AB20: 1.0252759 | AD20: Moda | AE20: 2259.382 | AF20: 2761.455 | AG20: 2660.1213 | AH20: 2727.5678 | AI20: 2533.2107 | AJ20: 2532.6059 | AK20: 2579.0571 | AN20: Ecommerce | AO20: 0.11097411 | AP20: 0.10823529 | AQ20: 0.10114943 | AR20: 0.11099253 | AS20: 0.086382114 | AT20: 0.1073501 | AU20: 0.62508357
B21: Restaurantes | C21: 133 | D21: 159 | E21: 159 | F21: 176 | G21: 171 | H21: 207 | I21: 1005 | K21: Restaurantes | L21: 137 | M21: 164 | N21: 161 | O21: 182 | P21: 190 | Q21: 221 | R21: 1055 | U21: Restaurantes | V21: 1.0300752 | W21: 1.0314465 | X21: 1.0125786 | Y21: 1.0340909 | Z21: 1.1111111 | AA21: 1.0676329 | AB21: 1.0478225 | AD21: Restaurantes | AE21: 1230.7228 | AF21: 1197.0707 | AG21: 1204.7978 | AH21: 1212.6774 | AI21: 1253.9453 | AJ21: 1239.884 | AK21: 1223.183 | AN21: Gasolineras | AO21: 0.10357583 | AP21: 0.097647059 | AQ21: 0.11034483 | AR21: 0.10885806 | AS21: 0.095528455 | AT21: 0.092843327 | AU21: 0.60879756
B22: Supermercados | C22: 221 | D22: 200 | E22: 212 | F22: 189 | G22: 207 | H22: 191 | I22: 1220 | K22: Supermercados | L22: 238 | M22: 216 | N22: 228 | O22: 200 | P22: 240 | Q22: 234 | R22: 1356 | U22: Supermercados | V22: 1.0769231 | W22: 1.08 | X22: 1.0754717 | Y22: 1.0582011 | Z22: 1.1594203 | AA22: 1.2251309 | AB22: 1.1125245 | AD22: Supermercados | AE22: 1515.4469 | AF22: 1721.1879 | AG22: 1509.4511 | AH22: 1629.3512 | AI22: 1517.3984 | AJ22: 1596.6255 | AK22: 1581.5768 | AN22: Moda | AO22: 0.10727497 | AP22: 0.11058824 | AQ22: 0.082758621 | AR22: 0.10138741 | AS22: 0.10569106 | AT22: 0.096711799 | AU22: 0.60441209
B23: Masivo | C23: 1377 | D23: 1425 | E23: 1457 | F23: 1520 | G23: 1598 | H23: 1705 | I23: 9082 | K23: Masivo | L23: 1455 | M23: 1496 | N23: 1569 | O23: 1614 | P23: 1716 | Q23: 1810 | R23: 9660 | U23: Masivo | V23: 1.0491188 | W23: 1.0458852 | X23: 1.0744548 | Y23: 1.0611888 | Z23: 1.0686793 | AA23: 1.0563825 | AB23: 1.0592849 | AD23: Masivo | AE23: 2395.0929 | AF23: 2484.019 | AG23: 2538.5439 | AH23: 2374.238 | AI23: 2358.4429 | AJ23: 2370.7914 | AK23: 2420.188 | AN23: Masivo | AO23: 1 | AP23: 1 | AQ23: 1 | AR23: 1 | AS23: 1 | AT23: 1 | AU23: 6
B24: Ecommerce | C24: 146 | D24: 140 | E24: 147 | F24: 164 | G24: 164 | H24: 161 | I24: 922 | K24: Ecommerce | L24: 149 | M24: 145 | N24: 156 | O24: 168 | P24: 178 | Q24: 166 | R24: 962 | U24: Ecommerce | V24: 1.0205479 | W24: 1.0357143 | X24: 1.0612245 | Y24: 1.0243902 | Z24: 1.0853659 | AA24: 1.0310559 | AB24: 1.0430498 | AD24: Ecommerce | AE24: 3074.2866 | AF24: 2992.3874 | AG24: 3524.7053 | AH24: 3030.7941 | AI24: 3142.5479 | AJ24: 3117.687 | AK24: 3147.068 | AN24: Supermercados | AO24: 0.26254296 | AP24: 0.27941176 | AQ24: 0.23709369 | AR24: 0.21747212 | AS24: 0.20629371 | AT24: 0.21325967 | AU24: 1.4160739
B25: Electronica | C25: 103 | D25: 107 | E25: 156 | F25: 165 | G25: 185 | H25: 229 | I25: 945 | K25: Electronica | L25: 108 | M25: 111 | N25: 176 | O25: 174 | P25: 196 | Q25: 239 | R25: 1004 | U25: Electronica | V25: 1.0485437 | W25: 1.0373832 | X25: 1.1282051 | Y25: 1.0545455 | Z25: 1.0594595 | AA25: 1.0436681 | AB25: 1.0619675 | AD25: Electronica | AE25: 5121.66 | AF25: 6037.2034 | AG25: 5330.8223 | AH25: 5251.8758 | AI25: 5148.0371 | AJ25: 5541.9867 | AK25: 5405.2642 | AN25: Restaurantes | AO25: 0.18281787 | AP25: 0.16911765 | AQ25: 0.17463352 | AR25: 0.19516729 | AS25: 0.21153846 | AT25: 0.21657459 | AU25: 1.1498494
... B38: Supermercados | C38: 141 | D38: 145 | E38: 138 | F38: 146 | G38: 142 | H38: 144 | I38: 856 | K38: Supermercados | L38: 151 | M38: 158 | N38: 145 | O38: 153 | P38: 148 | Q38: 163 | R38: 918 | U38: Supermercados | V38: 1.070922 | W38: 1.0896552 | X38: 1.0507246 | Y38: 1.0479452 | Z38: 1.0422535 | AA38: 1.1319444 | AB38: 1.0722408 | AD38: Supermercados | AE38: 1541.8258 | AF38: 1664.0685 | AG38: 1623.8928 | AH38: 1383.4006 | AI38: 1465.2945 | AJ38: 1456.3612 | AK38: 1522.4739 | AN38: Ecommerce | AO38: 0.082191781 | AP38: 0.12135177 | AQ38: 0.096875 | AR38: 0.12724758 | AS38: 0.096100279 | AT38: 0.087067862 | AU38: 0.61083427
B39: Total general | C39: 3036 | D39: 3129 | E39: 3221 | F39: 3415 | G39: 3542 | H39: 3750 | I39: 20093 | K39: Total general | L39: 3191 | M39: 3294 | N39: 3408 | O39: 3625 | P39: 3813 | Q39: 4036 | R39: 21367 | U39: Promedio general | V39: 1.0427832 | W39: 1.0482945 | X39: 1.0475136 | Y39: 1.057393 | Z39: 1.0716925 | AA39: 1.0737075 | AB39: 1.0568974 | AD39: Promedio general | AE39: 2346.3099 | AF39: 2383.5119 | AG39: 2448.7758 | AH39: 2367.86 | AI39: 2329.9027 | AJ39: 2371.8326 | AK39: 2374.6988

Sheet 03_KPIs (2)
B1: <<INDICE | C1: <<Anexos
B3: KPIS
U4: Resumen de comportamiento
B5: Clientes Activos | U5: variable | V5: granularidad | W5: resultado
B6: Segmento/Tipo Comercio | C6: 01-2023 | D6: 02-2023 | E6: 03-2023 | F6: 04-2023 | G6: 05-2023 | H6: 06-2023 | I6: Total general | U6: # transf | V6: por tipo de comercio | W6: restaurantes aumenta, seguido de electronica
B7: Masivo | C7: 0.45355731 | D7: 0.45541707 | E7: 0.45234399 | F7: 0.44509517 | G7: 0.45115754 | H7: 0.45466667 | I7: 0.45199821 | V7: por tipo de comercio y segmento | W7: Supermercado lidera en todos los segmentos, seguido de restaurantes quien tiene una tendencia de crecimiento en casi todos los segmentos a lo largo del tiempo
B8: Supermercados | C8: 0.25054466 | D8: 0.27649123 | E8: 0.23198353 | F8: 0.21973684 | G8: 0.20212766 | H8: 0.20821114 | I8: 0.23001542 | U8: Cientes activos | V8: por segmento | W8: casi la mitad (+45%) de clientes activos están dentro del segmento masivo, electronica y restaurantes muestran consistencia en aumento sobre todo electronica
B9: Restaurantes | C9: 0.18300654 | D9: 0.1677193 | E9: 0.17913521 | F9: 0.19144737 | G9: 0.20650814 | H9: 0.21407625 | I9: 0.19136754
B10: Farmacias | C10: 0.15976761 | D10: 0.15087719 | E10: 0.1757035 | F10: 0.15986842 | G10: 0.16395494 | H10: 0.16246334 | I10: 0.16218895
B11: Gasolineras | C11: 0.10384895 | D11: 0.11929825 | E11: 0.11256005 | F11: 0.11447368 | G11: 0.099499374 | H11: 0.10674487 | I11: 0.10922704
B12: Electronica | C12: 0.07480029 | D12: 0.075087719 | E12: 0.10706932 | F12: 0.10855263 | G12: 0.11576971 | H12: 0.13431085 | I12: 0.10405197
B13: Moda | C13: 0.12200436 | D13: 0.1122807 | E13: 0.092656143 | F13: 0.098026316 | G13: 0.10951189 | H13: 0.079765396 | I13: 0.1016296
B14: Ecommerce | C14: 0.1060276 | D14: 0.098245614 | E14: 0.10089224 | F14: 0.10789474 | G14: 0.10262829 | H14: 0.094428152 | I14: 0.10151949
B15: Joven | C15: 0.25494071 | D15: 0.25950783 | E15: 0.25954672 | F15: 0.25827233 | G15: 0.25522304 | H15: 0.2536 | I15: 0.25675608
B16: Supermercados | C16: 0.28552972 | D16: 0.24630542 | E16: 0.25358852 | F16: 0.21428571 | G16: 0.2289823 | H16: 0.20084122 | I16: 0.23647994
B17: Restaurantes | C17: 0.17183463 | D17: 0.19581281 | E17: 0.19019139 | F17: 0.19954649 | G17: 0.18915929 | H17: 0.21766562 | I17: 0.19480519
B18: Farmacias | C18: 0.14470284 | D18: 0.13916256 | E18: 0.14114833 | F18: 0.14285714 | G18: 0.15707965 | H18: 0.14511041 | I18: 0.14518318
B19: Electronica | C19: 0.069767442 | D19: 0.10098522 | E19: 0.11602871 | F19: 0.12471655 | G19: 0.125 | H19: 0.12197687 | I19: 0.1108742
B20: Ecommerce | C20: 0.11498708 | D20: 0.10221675 | E20: 0.10287081 | F20: 0.1031746 | G20: 0.092920354 | H20: 0.11461619 | I20: 0.10505912
... B39: Total general | C39: 1 | D39: 1 | E39: 1 | F39: 1 | G39: 1 | H39: 1 | I39: 1
B45: Transacciones Totales
B46: Segmento/Tipo Comercio | C46: 44927 | D46: 44958 | E46: 44986 | F46: 45017 | G46: 45047 | H46: 45078 | I46: Total general
B47: Masivo | C47: 1455 | D47: 1496 | E47: 1569 | F47: 1614 | G47: 1716 | H47: 1810 | I47: 9660
B48: Supermercados | C48: 382 | D48: 418 | E48: 372 | F48: 351 | G48: 354 | H48: 386 | I48: 2263
B49: Restaurantes | C49: 266 | D49: 253 | E49: 274 | F49: 315 | G49: 363 | H49: 392 | I49: 1863
B50: Farmacias | C50: 226 | D50: 227 | E50: 277 | F50: 258 | G50: 278 | H50: 294 | I50: 1560
B51: Gasolineras | C51: 150 | D51: 176 | E51: 173 | F51: 188 | G51: 167 | H51: 189 | I51: 1043
B52: Electronica | C52: 108 | D52: 111 | E52: 176 | F52: 174 | G52: 196 | H52: 239 | I52: 1004
B53: Moda | C53: 174 | D53: 166 | E53: 141 | F53: 160 | G53: 180 | H53: 144 | I53: 965
B54: Ecommerce | C54: 149 | D54: 145 | E54: 156 | F54: 168 | G54: 178 | H54: 166 | I54: 962
B55: Joven | C55: 811 | D55: 850 | E55: 870 | F55: 937 | G55: 984 | H55: 1034 | I55: 5486
B56: Supermercados | C56: 238 | D56: 216 | E56: 228 | F56: 200 | G56: 240 | H56: 234 | I56: 1356
B57: Restaurantes | C57: 137 | D57: 164 | E57: 161 | F57: 182 | G57: 190 | H57: 221 | I57: 1055
B58: Farmacias | C58: 120 | D58: 118 | E58: 122 | F58: 130 | G58: 149 | H58: 149 | I58: 788
... B79: Total general | C79: 3191 | D79: 3294 | E79: 3408 | F79: 3625 | G79: 3813 | H79: 4036 | I79: 21367
B87: Frecuencia Promedio (Transacciones promedio por cliente activo)
B88: Segmento/Tipo Comercio | C88: 44927 | D88: 44958 | E88: 44986 | F88: 45017 | G88: 45047 | H88: 45078 | I88: Promedio general
B89: Masivo | C89: 1.0491188 | D89: 1.0458852 | E89: 1.0744548 | F89: 1.0611888 | G89: 1.0686793 | H89: 1.0563825 | I89: 1.0592849
B90: Supermercados | C90: 1.1072464 | D90: 1.0609137 | E90: 1.1005917 | F90: 1.0508982 | G90: 1.0959752 | H90: 1.0873239 | I90: 1.0838249
B91: Restaurantes | C91: 1.0555556 | D91: 1.0585774 | E91: 1.0498084 | F91: 1.0824742 | G91: 1.1 | H91: 1.0739726 | I91: 1.0700647
...

Sheet 04_Gráficos
A1: <<INDICE
C25: Etiquetas de fila
C26: Ecommerce
C27: Empresarial
C28: Joven
C29: Masivo
C30: Premium
C31: Electronica
C32: Empresarial
C33: Joven
C34: Masivo
C35: Premium
C36: Farmacias
... C61: Total general

Sheet 05_DQC
B1: <<INDICE
B3: DQC
B4: Regla | C4: Tabla | D4: Indicencias | E4: % sobre total
B5: Fechas fuera de rango (ene–jun 2023) | C5: Transacciones | D5: 43 | E5: =D5/21620 -> 0.0019888992
B6: Montos ≤0, | C6: Transacciones | D6: 43 | E6: =D6/21620 -> 0.0019888992
B7: Clientes marcados como INACTIVOS con transacciones en el período ene–jun 2023 | C7: Clientes / Transacciones | D7: 158 | E7: =D7/5543 -> 0.02850442

Sheet 06_RFT
B2: <<INDICE | C2: <<Anexos
B4: RFT
B6: Segmento/cliente | C6: Frecuencia | D6: Recencia | E6: Ticket Promedio
B7: Empresarial | C7: 2143 | D7: 21595 | E7: 1138051.5
B8: Joven | C8: 5536 | D8: 61544 | E8: 3008420.7
B9: Masivo | C9: 9762 | D9: 103922 | E9: 5181914.4
B10: Premium | C10: 4136 | D10: 49671 | E10: 2240199.2
B11: Total general | C11: 21577 | D11: 236732 | E11: 11568586

Sheet 07_I&R
B1: <<INDICE
B3: Storytelling: insights y recomendaciones accionables.
B5: INSIGHT 1 – Restaurantes como motor de crecimiento transversal
B6: *Evidencia: La participación de Restaurantes crece de 0.65 a 0.85 entre enero y junio (+31%). El crecimiento se observa en todos los segmentos, especialmente en Masivo (transacciones de 266 a 392) y Joven (de 137 a 221). La frecuencia promedio se mantiene estable (~1.05–1.10), lo que indica incorporación de nuevos clientes más que sobreconsumo. | E6: =0.85-0.65 -> 0.2
B7: *Interpretación: El crecimiento proviene de más clientes activos mes a mes, no de un aumento en la frecuencia individual.
B8: *Recomendación: Priorizar alianzas con restaurantes mediante cashback segmentado para Masivo y Joven, promociones en días de alta recurrencia (viernes a domingo) y uso de Restaurantes como puerta de entrada para cross-sell hacia otros rubros.
B11: INSIGHT 2 – Supermercados domina en volumen, pero pierde participación
B12: *Evidencia: Es el tipo de comercio con mayor participación absoluta (total acumulado 5.70), pero su participación cae de 1.07 a 0.87. Aunque las transacciones crecen, lo hacen a un ritmo menor que otros rubros como Restaurantes y Electrónica.
B13: *Interpretación: Supermercados es un rubro maduro, con alto volumen pero bajo crecimiento relativo.
B14: *Recomendación: No priorizar inversión en adquisición. Enfocar esfuerzos en optimización de rentabilidad mediante promociones con ticket mínimo, beneficios dirigidos a clientes de alto valor y uso del rubro como ancla de retención más que de expansión.
B17: INSIGHT 3 – Electrónica crece menos en clientes, pero más en valor
B18: *Evidencia: La participación aumenta de 0.31 a 0.54. Presenta un ticket promedio alto y estable (Masivo ~RD$5,400; Joven ~RD$5,300) y una frecuencia baja (~1.05), consistente con compras ocasionales.
B19: *Interpretación: Electrónica es un driver de ingresos más que de volumen transaccional.
B20: *Recomendación: Implementar campañas específicas en fechas clave (quincena, bonos, Black Friday), ofrecer financiamiento o cuotas para mejorar conversión y enfocar el targeting en segmentos Premium y Masivo.
B23: INSIGHT 4 – El segmento Masivo concentra el mayor impacto total
B24: *Evidencia: Es el segmento con más clientes activos (1,705 en junio 2023), mayor número de transacciones acumuladas (9,660 ene–jun) y mayor ticket total (~RD$5.18 MM).
... B29: Usarlo como ancla de retención, no de expansión.

Sheet TRANSACCIONES
A1: ID_CUENTA | B1: ID_TRANSACCION | C1: FECHA_COMPRA | D1: MONTO_RD | E1: ID_COMERCIO
A2: 103287 | B2: 1 | C2: 44937.683 | D2: 680.14 | E2: 9
A3: 104453 | B3: 2 | C3: 44940.567 | D3: 1051.59 | E3: 74
A4: 101205 | B4: 3 | C4: 44937.529 | D4: 1111.4 | E4: 149
A5: 100552 | B5: 4 | C5: 44949.785 | D5: 2406.93 | E5: 40
A6: 106437 | B6: 5 | C6: 44939.425 | D6: 1994.11 | E6: 193
A7: 106418 | B7: 6 | C7: 44931.424 | D7: 1213.61 | E7: 85
A8: 101939 | B8: 7 | C8: 44940.829 | D8: 116.51 | E8: 116
A9: 104078 | B9: 8 | C9: 44935.773 | D9: 976.12 | E9: 189
A10: 100118 | B10: 9 | C10: 44950.599 | D10: 6537.43 | E10: 2
A11: 100822 | B11: 10 | C11: 44938.686 | D11: 1052.61 | E11: 172
A12: 102979 | B12: 11 | C12: 44952.472 | D12: 6296.32 | E12: 7
A13: 105991 | B13: 12 | C13: 44947.602 | D13: 2609.2 | E13: 132
... A21621: 100240 | B21621: 21620 | C21621: 44989.783 | D21621: 4816.18 | E21621: 121

Sheet CLIENTES
A1: ID_CLIENTE | B1: ID_CUENTA | C1: FECHA_NACIMIENTO | D1: SEXO | E1: STATUS_CLIENTE
A2: 1 | B2: 100001 | C2: 30132 | D2: M | E2: ACTIVO
A3: 2 | B3: 100002 | C3: 33054 | D3: F | E3: ACTIVO
A4: 3 | B4: 100003 | C4: 29402 | D4: M | E4: ACTIVO
A5: 4 | B5: 100004 | C5: 25749 | D5: F | E5: ACTIVO
A6: 5 | B6: 100005 | C6: 33419 | D6: F | E6: ACTIVO
A7: 6 | B7: 100006 | C7: 33419 | D7: F | E7: INACTIVO
A8: 7 | B8: 100007 | C8: 25384 | D8: F | E8: ACTIVO
A9: 8 | B9: 100008 | C9: 29036 | D9: F | E9: ACTIVO
A10: 9 | B10: 100009 | C10: 34515 | D10: M | E10: ACTIVO
A11: 10 | B11: 100010 | C11: 29767 | D11: F | E11: ACTIVO
A12: 11 | B12: 100011 | C12: 34515 | D12: M | E12: ACTIVO
A13: 12 | B13: 100012 | C13: 34515 | D13: F | E13: ACTIVO
... A6501: 6500 | B6501: 106500 | C6501: 33785 | D6501: M | E6501: ACTIVO

Sheet SEGMENTOS
A1: ID_CLIENTE | B1: SEGMENTO_ACTUAL | C1: FECHA_INICIO_SEGMENTO | D1: STATUS_CLIENTE
A2: 1 | B2: Empresarial | C2: 44853 | D2: =VLOOKUP(A2,CLIENTES!$A$1:$E$6501,5,FALSE) -> ACTIVO
A3: 2 | B3: Joven | C3: 44764 | D3: =VLOOKUP(A3,CLIENTES!$A$1:$E$6501,5,FALSE) -> ACTIVO
A4: 3 | B4: Masivo | C4: 44798 | D4: =VLOOKUP(A4,CLIENTES!$A$1:$E$6501,5,FALSE) -> ACTIVO
A5: 4 | B5: Masivo | C5: 44706 | D5: =VLOOKUP(A5,CLIENTES!$A$1:$E$6501,5,FALSE) -> ACTIVO
A6: 5 | B6: Masivo | C6: 44581 | D6: =VLOOKUP(A6,CLIENTES!$A$1:$E$6501,5,FALSE) -> ACTIVO
A7: 6 | B7: Joven | C7: 44758 | D7: =VLOOKUP(A7,CLIENTES!$A$1:$E$6501,5,FALSE) -> INACTIVO
A8: 7 | B8: Masivo | C8: 44621 | D8: =VLOOKUP(A8,CLIENTES!$A$1:$E$6501,5,FALSE) -> ACTIVO
A9: 8 | B9: Masivo | C9: 44701 | D9: =VLOOKUP(A9,CLIENTES!$A$1:$E$6501,5,FALSE) -> ACTIVO
A10: 9 | B10: Masivo | C10: 44901 | D10: =VLOOKUP(A10,CLIENTES!$A$1:$E$6501,5,FALSE) -> ACTIVO
A11: 10 | B11: Joven | C11: 44644 | D11: =VLOOKUP(A11,CLIENTES!$A$1:$E$6501,5,FALSE) -> ACTIVO
A12: 11 | B12: Premium | C12: 44647 | D12: =VLOOKUP(A12,CLIENTES!$A$1:$E$6501,5,FALSE) -> ACTIVO
A13: 12 | B13: Joven | C13: 44912 | D13: =VLOOKUP(A13,CLIENTES!$A$1:$E$6501,5,FALSE) -> ACTIVO
... A6501: 6500 | B6501: Masivo | C6501: 44747 | D6501: =VLOOKUP(A6501,CLIENTES!$A$1:$E$6501,5,FALSE) -> ACTIVO

Sheet COMERCIO
A1: ID_COMERCIO | B1: NOMBRE_COMERCIO | C1: TIPO_COMERCIO
A2: 1 | B2: Comercio_001 | C2: SUPERMERCADOS
A3: 2 | B3: Comercio_002 | C3: ELECTRONICA
A4: 3 | B4: Comercio_003 | C4: SUPERMERCADOS
A5: 4 | B5: Comercio_004 | C5: SUPERMERCADOS
A6: 5 | B6: Comercio_005 | C6: RESTAURANTES
A7: 6 | B7: Comercio_006 | C7: MODA
A8: 7 | B8: Comercio_007 | C8: ELECTRONICA
A9: 8 | B9: Comercio_008 | C9: FARMACIAS
A10: 9 | B10: Comercio_009 | C10: SUPERMERCADOS
A11: 10 | B11: Comercio_010 | C11: GASOLINERAS
A12: 11 | B12: Comercio_011 | C12: RESTAURANTES
A13: 12 | B13: Comercio_012 | C13: MODA
... A201: 200 | B201: Comercio_200 | C201: ECOMMERCE

Sheet DATA_DICTIONARY
A1: TABLA | B1: CAMPO | C1: TIPO | D1: DESCRIPCION
A2: CLIENTES | B2: ID_CLIENTE | C2: INT | D2: Identificador único del cliente
A3: CLIENTES | B3: ID_CUENTA | C3: INT | D3: Identificador único de la cuenta
A4: CLIENTES | B4: FECHA_NACIMIENTO | C4: DATE | D4: Fecha de nacimiento (edades 18–80)
A5: CLIENTES | B5: SEXO | C5: CHAR(1) | D5: Sexo: M/F
A6: CLIENTES | B6: STATUS_CLIENTE | C6: VARCHAR | D6: Estado del cliente: ACTIVO/INACTIVO (~85/15)
A7: COMERCIO | B7: ID_COMERCIO | C7: INT | D7: Identificador único del comercio
A8: COMERCIO | B8: NOMBRE_COMERCIO | C8: VARCHAR | D8: Nombre del comercio
A9: COMERCIO | B9: TIPO_COMERCIO | C9: VARCHAR | D9: Categoría: SUPERMERCADOS, RESTAURANTES, FARMACIAS, ELECTRONICA, GASOLINERAS, MODA, ECOMMERCE
A10: TRANSACCIONES | B10: ID_TRANSACCION | C10: INT | D10: Identificador único de la transacción
A11: TRANSACCIONES | B11: ID_CUENTA | C11: INT | D11: Identificador único de la cuenta
A12: TRANSACCIONES | B12: FECHA_COMPRA | C12: TIMESTAMP | D12: Fecha y hora de la compra (ene–jun 2023)
... A17: SEGMENTOS | B17: FECHA_INICIO_SEGMENTO | C17: DATE | D17: Fecha de asignación del segmento (año 2022)
